Workbook

Sheet Raw Data
A1: Brand Name | B1: Product Name | C1: Quantity | D1: Platform | E1: Pin Code | F1: Area | G1: MRP (₹) | H1: Selling Price (₹) | I1: Discount (%) | J1: Stock Status | K1: Delivery Time (min) | L1: offer
A2: =LEFT(B2, FIND(" ",B2)-1) -> 8x | B2: 8x Bottle of 120ml Shampoo | C2: 120 ml | D2: Blinkit | E2: 560034 | F2: Koramangala | G2: ₹297 | H2: ₹345 | I2: 13% OFF | J2: In Stock | K2: 18 mins | L2: 0.13
A3: =LEFT(B3, FIND(" ",B3)-1) -> 8X | B3: 8X KT Shampoo | C3: 60 ml | D3: Blinkit | E3: 560034 | F3: Koramangala | G3: ₹447 | H3: ₹471 | I3: 5% OFF | J3: In Stock | K3: 18 mins | L3: 0.05
A4: =LEFT(B4, FIND(" ",B4)-1) -> Anveshan | B4: Anveshan Cold Pressed Virgin Coconut Oil (Thengina Enne) | C4: 250 ml | D4: Blinkit | E4: 560034 | F4: Koramangala | G4: ₹283 | H4: ₹350 | I4: 19% OFF | J4: In Stock | K4: 18 mins | L4: 0.19
A5: =LEFT(B5, FIND(" ",B5)-1) -> Arata | B5: Arata Damage Defence Super Hair Serum | C5: 30 ml | D5: Blinkit | E5: 560034 | F5: Koramangala | G5: ₹383 | H5: ₹450 | I5: 14% OFF | J5: In Stock | K5: 18 mins | L5: 0.14
A6: =LEFT(B6, FIND(" ",B6)-1) -> Arata | B6: Arata Hair Growth Shampoo & Serum Everyday Combo | C6: 330 ml | D6: Blinkit | E6: 560034 | F6: Koramangala | G6: ₹462 | H6: ₹599 | I6: 22% OFF | J6: In Stock | K6: 18 mins | L6: 0.22
A7: =LEFT(B7, FIND(" ",B7)-1) -> Aroma | B7: Aroma Magic Castor Oil | C7: 100 ml | D7: Blinkit | E7: 560034 | F7: Koramangala | G7: ₹118 | H7: ₹138 | I7: 14% OFF | J7: In Stock | K7: 18 mins | L7: 0.14
A8: =LEFT(B8, FIND(" ",B8)-1) -> Aswini | B8: Aswini Homeo Arnica Hair Oil | C8: 180 ml | D8: Blinkit | E8: 560034 | F8: Koramangala | G8: ₹315 | H8: ₹351 | I8: 10% OFF | J8: In Stock | K8: 21 mins | L8: 0.1
A9: =LEFT(B9, FIND(" ",B9)-1) -> Aveeno | B9: Aveeno Daily Moisturise Baby Wash & Shampoo | C9: 532 ml | D9: Blinkit | E9: 560034 | F9: Koramangala | G9: ₹880 | J9: In Stock | K9: 18 mins | L9: NULL
A10: =LEFT(B10, FIND(" ",B10)-1) -> Avimee | B10: Avimee Herbal Rosemary Hair Oil | C10: 100 ml | D10: Blinkit | E10: 560034 | F10: Koramangala | G10: ₹330 | H10: ₹550 | I10: 40% OFF | J10: In Stock | K10: 21 mins | L10: 0.4
A11: =LEFT(B11, FIND(" ",B11)-1) -> Avimee | B11: Avimee Herbal Scalptone Hair Growth Serum | C11: 25 ml | D11: Blinkit | E11: 560034 | F11: Koramangala | G11: ₹699 | H11: ₹885 | I11: 21% OFF | J11: In Stock | K11: 18 mins | L11: 0.21
A12: =LEFT(B12, FIND(" ",B12)-1) -> Bajaj | B12: Bajaj Almond Drops Non-Sticky Hair Oil 95 ml | C12: 95 ml | D12: Blinkit | E12: 560034 | F12: Koramangala | G12: ₹85 | J12: In Stock | K12: 21 mins | L12: NULL
A13: =LEFT(B13, FIND(" ",B13)-1) -> Bajaj | B13: Bajaj Almond Drops Non-Sticky Hair Oil | C13: 340 ml | D13: Blinkit | E13: 560034 | F13: Koramangala | G13: ₹216 | H13: ₹335 | I13: 35% OFF | J13: In Stock | K13: 18 mins | L13: 0.35
A14: =LEFT(B14, FIND(" ",B14)-1) -> Bajaj | B14: Bajaj Almond Drops Non-Sticky Hair Oil 185 ml | C14: 185 ml | D14: Blinkit | E14: 560034 | F14: Koramangala | G14: ₹165 | J14: In Stock | K14: 18 mins | L14: NULL
A15: =LEFT(B15, FIND(" ",B15)-1) -> Bajaj | B15: Bajaj Aloe Vera Amla Hair Oil 3x Softer | C15: 500 ml | D15: Blinkit | E15: 560034 | F15: Koramangala | G15: ₹120 | H15: ₹145 | I15: 17% OFF | J15: In Stock | K15: 21 mins | L15: 0.17
A16: =LEFT(B16, FIND(" ",B16)-1) -> Bajaj | B16: Bajaj Castor Hair Oil | C16: 200 ml | D16: Blinkit | E16: 560034 | F16: Koramangala | G16: ₹164 | H16: ₹270 | I16: 39% OFF | J16: In Stock | K16: 18 mins | L16: 0.39
A17: =LEFT(B17, FIND(" ",B17)-1) -> Bajaj | B17: Bajaj 100% Pure Grade 1 Coconut Oil | C17: 600 ml | D17: Blinkit | E17: 560034 | F17: Koramangala | G17: ₹326 | H17: ₹560 | I17: 41% OFF | J17: In Stock | K17: 18 mins | L17: 0.41
A18: =LEFT(B18, FIND(" ",B18)-1) -> Bajaj | B18: Bajaj 100% Pure Grade 1 Coconut Oil | C18: 600 ml | D18: Blinkit | E18: 560034 | F18: Koramangala | G18: ₹369 | H18: ₹665 | I18: 44% OFF | J18: In Stock | K18: 21 mins | L18: 0.44
A19: =LEFT(B19, FIND(" ",B19)-1) -> Bajaj | B19: Bajaj Almond Drops Non-Sticky Hair Oil 185 ml | C19: 185 ml | D19: Blinkit | E19: 560034 | F19: Koramangala | G19: ₹1,350 | H19: ₹1,500 | I19: 10% OFF | J19: In Stock | K19: 21 mins | L19: 0.1
A20: =LEFT(B20, FIND(" ",B20)-1) -> Bajaj | B20: Bajaj Aloe Vera Amla Hair Oil 3x Softer | C20: 500 ml | D20: Blinkit | E20: 560034 | F20: Koramangala | G20: ₹469 | H20: ₹495 | I20: 5% OFF | J20: In Stock | K20: 21 mins | L20: 0.05
A21: =LEFT(B21, FIND(" ",B21)-1) -> Bajaj | B21: Bajaj 100% Pure Grade 1 Coconut Oil | C21: 600 ml | D21: Blinkit | E21: 560034 | F21: Koramangala | G21: ₹279 | H21: ₹295 | I21: 5% OFF | J21: In Stock | K21: 18 mins | L21: 0.05
A22: =LEFT(B22, FIND(" ",B22)-1) -> Bajaj | B22: Bajaj Castor Hair Oil | C22: 200 ml | D22: Blinkit | E22: 560034 | F22: Koramangala | G22: ₹380 | H22: ₹446 | I22: 14% OFF | J22: In Stock | K22: 18 mins | L22: 0.14
A23: =LEFT(B23, FIND(" ",B23)-1) -> Bajaj | B23: Bajaj Almond Drops Hair Serum | C23: 50 ml | D23: Blinkit | E23: 560034 | F23: Koramangala | G23: ₹248 | H23: ₹249 | J23: In Stock | K23: 18 mins | L23: NULL
A24: =LEFT(B24, FIND(" ",B24)-1) -> Bajaj | B24: Bajaj Almond Drops Hair Serum | C24: 100 ml | D24: Blinkit | E24: 560034 | F24: Koramangala | G24: ₹450 | H24: ₹499 | I24: 9% OFF | J24: In Stock | K24: 21 mins | L24: 0.09
A25: Bajaj Consumer Care | B25: Bajaj Almond Drops Anti Hairfall Shampoo with Almond Oil & Vitamin E for Men and Women | C25: 1 pack (340 ml) | D25: Zepto | E25: 560034 | F25: Koramangala | G25: 219 | H25: ₹399 | I25: 45% Off | J25: In Stock | K25: 18 mins | L25: 0.45
A26: Bajaj Consumer Care | B26: Bajaj Almond Drops Anti Hairfall Shampoo with Almond Oil & Vitamin E for Men and Women | C26: 1 pack (340 ml) | D26: Zepto | E26: 560034 | F26: Koramangala | G26: 219 | H26: ₹399 | I26: 45% Off | J26: In Stock | K26: 18 mins | L26: 0.45
A27: Bajaj Consumer Care | B27: Bajaj Almond Drops Anti Hairfall Shampoo with Almond Oil & Vitamin E for Men and Women | C27: 1 pack (340 ml) | D27: Zepto | E27: 560034 | F27: Koramangala | G27: 219 | H27: ₹399 | I27: 45% Off | J27: In Stock | K27: 18 mins | L27: 0.45
A28: =LEFT(B28, FIND(" ",B28)-1) -> Bare | B28: Bare Anatomy Ultra Smoothing Hair Serum | C28: 50 ml | D28: Blinkit | E28: 560034 | F28: Koramangala | G28: ₹164 | H28: ₹270 | I28: 39% OFF | J28: In Stock | K28: 18 mins | L28: 0.39
A29: =LEFT(B29, FIND(" ",B29)-1) -> Bare | B29: Bare Anatomy Advanced Hair Growth Serum | C29: 30 ml | D29: Blinkit | E29: 560034 | F29: Koramangala | G29: ₹149 | H29: ₹200 | I29: 25% OFF | J29: In Stock | K29: 18 mins | L29: 0.25
A30: =LEFT(B30, FIND(" ",B30)-1) -> Bare | B30: Bare Anatomy Argan & Vitamin E Anti-Frizz Hair Serum | C30: 75 ml | D30: Blinkit | E30: 560034 | F30: Koramangala | G30: ₹405 | H30: ₹449 | I30: 9% OFF | J30: In Stock | K30: 18 mins | L30: 0.09
A31: =LEFT(B31, FIND(" ",B31)-1) -> Bare | B31: Bare Anatomy Anti-Dandruff Shampoo | C31: 250 ml | D31: Blinkit | E31: 560034 | F31: Koramangala | G31: ₹148 | H31: ₹185 | I31: 20% OFF | J31: In Stock | K31: 19 mins | L31: 0.2
A32: =LEFT(B32, FIND(" ",B32)-1) -> Bare | B32: Bare Anatomy Anti-Hairfall Shampoo | C32: 250 ml | D32: Blinkit | E32: 560034 | F32: Koramangala | G32: ₹399 | H32: ₹499 | I32: 20% OFF | J32: In Stock | K32: 21 mins | L32: 0.2
A33: =LEFT(B33, FIND(" ",B33)-1) -> Bare | B33: Bare Anatomy Color Protect Shampoo | C33: 250 ml | D33: Blinkit | E33: 560034 | F33: Koramangala | G33: ₹1,197 | H33: ₹1,379 | I33: 13% OFF | J33: In Stock | K33: 21 mins | L33: 0.13
A34: =LEFT(B34, FIND(" ",B34)-1) -> Bare | B34: Bare Anatomy Damage Repair Shampoo | C34: 250 ml | D34: Blinkit | E34: 560034 | F34: Koramangala | G34: ₹374 | H34: ₹440 | I34: 15% OFF | J34: In Stock | K34: 18 mins | L34: 0.15
A35: =LEFT(B35, FIND(" ",B35)-1) -> BBlunt | B35: BBlunt Intense Moisture Hair Serum | C35: 70 ml | D35: Blinkit | E35: 560034 | F35: Koramangala | G35: ₹459 | H35: ₹540 | I35: 15% OFF | J35: In Stock | K35: 21 mins | L35: 0.15
A36: Bblunt | B36: BBlunt Intense Moisture Hair Mask With Jojoba Oil & Vitamin E | C36: 1 pc (250 g) | D36: Zepto | E36: 560034 | F36: Koramangala | G36: 439 | H36: ₹499 | I36: 12% Off | J36: In Stock | K36: 18 mins | L36: 0.12
A37: =LEFT(B37, FIND(" ",B37)-1) -> Be | B37: Be Bodywise 3% Redensyl Hair Growth Serum Roll On | C37: 25 ml | D37: Blinkit | E37: 560034 | F37: Koramangala | G37: ₹180 | J37: In Stock | K37: 18 mins | L37: NULL
A38: =LEFT(B38, FIND(" ",B38)-1) -> Be | B38: Be Bodywise 3% Redensyl Hair Growth Serum Roll On | C38: 50 ml | D38: Blinkit | E38: 560034 | F38: Koramangala | G38: ₹162 | H38: ₹340 | I38: 52% OFF | J38: In Stock | K38: 18 mins | L38: 0.52
A39: =LEFT(B39, FIND(" ",B39)-1) -> Beardo | B39: Beardo Hair Serum with Argan Oil | C39: 50 ml | D39: Blinkit | E39: 560034 | F39: Koramangala | G39: ₹222 | H39: ₹295 | I39: 24% OFF | J39: In Stock | K39: 18 mins | L39: 0.24
A40: =LEFT(B40, FIND(" ",B40)-1) -> Beardo | B40: Beardo Beard & Hair Growth Oil for Men | C40: 30 ml | D40: Blinkit | E40: 560034 | F40: Koramangala | G40: ₹352 | H40: ₹440 | I40: 20% OFF | J40: In Stock | K40: 18 mins | L40: 0.2
...

Sheet Brand Summary
A1: Brand Name | B1: Available Platforms | C1: Avg Discount (%) | D1: Out of Stock Count
A2: Dove | B2: Blinkit,Zetpto,Swiggy | C2: =AVERAGEIFS('Raw Data'!L:L,'Raw Data'!A:A,'Brand Summary'!A2) -> 0.26787234 | D2: Null
A3: Pantene | B3: Blinkit,Zetpto,Swiggy | C3: =AVERAGEIFS('Raw Data'!L:L,'Raw Data'!A:A,'Brand Summary'!A3) -> 0.315 | D3: Null
A4: L'Oréal | B4: Blinkit,Zetpto,Swiggy | C4: =AVERAGEIFS('Raw Data'!L:L,'Raw Data'!A:A,'Brand Summary'!A4) -> 0.21833333 | D4: Null
A5: Tresemme | B5: Blinkit,Zetpto,Swiggy | C5: =AVERAGEIFS('Raw Data'!L:L,'Raw Data'!A:A,'Brand Summary'!A5) -> 0.238 | D5: Null
A6: Clinic Plus | B6: Blinkit,Zetpto,Swiggy | C6: =AVERAGEIFS('Raw Data'!L:L,'Raw Data'!A:A,'Brand Summary'!A6) -> 0.47 | D6: Null
A7: Head & Shoulders | B7: Blinkit,Zetpto,Swiggy | C7: =AVERAGEIFS('Raw Data'!L:L,'Raw Data'!A:A,'Brand Summary'!A7) -> 0.465 | D7: Null

Sheet Platform Comparison
A1: Platform | B1: No. of Brands Available | C1: Total Products | D1: Out of Stock Count | E1: Out of Stock Rate (%)
A2: Blinkit
A3: Zepto
A4: Instamart
